Traceback (most recent call last):
  File "/Library/Python/3.8/site-packages/urllib3/connection.py", line 174, in _new_conn
    conn = connection.create_connection(
  File "/Library/Python/3.8/site-packages/urllib3/util/connection.py", line 72, in create_connection
    for res in socket.getaddrinfo(host, port, family, socket.SOCK_STREAM):
  File "/Library/Developer/CommandLineTools/Library/Frameworks/Python3.framework/Versions/3.8/lib/python3.8/socket.py", line 918, in getaddrinfo
    for res in _socket.getaddrinfo(host, port, family, type, proto, flags):
socket.gaierror: [Errno 8] nodename nor servname provided, or not known

During handling of the above exception, another exception occurred:

Traceback (most recent call last):
  File "/Library/Python/3.8/site-packages/urllib3/connectionpool.py", line 703, in urlopen
    httplib_response = self._make_request(
  File "/Library/Python/3.8/site-packages/urllib3/connectionpool.py", line 386, in _make_request
    self._validate_conn(conn)
  File "/Library/Python/3.8/site-packages/urllib3/connectionpool.py", line 1040, in _validate_conn
    conn.connect()
  File "/Library/Python/3.8/site-packages/urllib3/connection.py", line 358, in connect
    conn = self._new_conn()
  File "/Library/Python/3.8/site-packages/urllib3/connection.py", line 186, in _new_conn
    raise NewConnectionError(
urllib3.exceptions.NewConnectionError: <urllib3.connection.HTTPSConnection object at 0x10e3dae80>: Failed to establish a new connection: [Errno 8] nodename nor servname provided, or not known

During handling of the above exception, another exception occurred:

Traceback (most recent call last):
  File "/Library/Python/3.8/site-packages/requests/adapters.py", line 440, in send
    resp = conn.urlopen(
  File "/Library/Python/3.8/site-packages/urllib3/connectionpool.py", line 785, in urlopen
    retries = retries.increment(
  File "/Library/Python/3.8/site-packages/urllib3/util/retry.py", line 592, in increment
    raise MaxRetryError(_pool, url, error or ResponseError(cause))
urllib3.exceptions.MaxRetryError: HTTPSConnectionPool(host='glytoucan.org', port=443): Max retries exceeded with url: /Structures/Glycans/G12344AO (Caused by NewConnectionError('<urllib3.connection.HTTPSConnection object at 0x10e3dae80>: Failed to establish a new connection: [Errno 8] nodename nor servname provided, or not known'))

During handling of the above exception, another exception occurred:

Traceback (most recent call last):
  File "/Users/rykahsay/projects/glygen-backend-api/glygen/misc.py", line 221, in post
    res_obj = testurls(req_obj, config_obj)
  File "/Users/rykahsay/projects/glygen-backend-api/glygen/misc_apilib.py", line 184, in testurls
    res = requests.get(url)
  File "/Library/Python/3.8/site-packages/requests/api.py", line 75, in get
    return request('get', url, params=params, **kwargs)
  File "/Library/Python/3.8/site-packages/requests/api.py", line 61, in request
    return session.request(method=method, url=url, **kwargs)
  File "/Library/Python/3.8/site-packages/requests/sessions.py", line 529, in request
    resp = self.send(prep, **send_kwargs)
  File "/Library/Python/3.8/site-packages/requests/sessions.py", line 645, in send
    r = adapter.send(request, **kwargs)
  File "/Library/Python/3.8/site-packages/requests/adapters.py", line 519, in send
    raise ConnectionError(e, request=request)
requests.exceptions.ConnectionError: HTTPSConnectionPool(host='glytoucan.org', port=443): Max retries exceeded with url: /Structures/Glycans/G12344AO (Caused by NewConnectionError('<urllib3.connection.HTTPSConnection object at 0x10e3dae80>: Failed to establish a new connection: [Errno 8] nodename nor servname provided, or not known'))
